2020-06-02 21:41:46 [scrapy] DEBUG: Crawled (200) <GET https://www.yelp.com/> (referer: None)
2020-06-02 21:42:12 [scrapy] ERROR: Spider error processing <GET https://www.yelp.com/> (referer: None)
Traceback (most recent call last):
  File "f:\web scrapping\yelp\venv\lib\site-packages\urllib3\connection.py", line 160, in _new_conn
    (self._dns_host, self.port), self.timeout, **extra_kw
  File "f:\web scrapping\yelp\venv\lib\site-packages\urllib3\util\connection.py", line 84, in create_connection
    raise err
  File "f:\web scrapping\yelp\venv\lib\site-packages\urllib3\util\connection.py", line 74, in create_connection
    sock.connect(sa)
ConnectionRefusedError: [WinError 10061] No connection could be made because the target machine actively refused it

During handling of the above exception, another exception occurred:

Traceback (most recent call last):
  File "f:\web scrapping\yelp\venv\lib\site-packages\urllib3\connectionpool.py", line 677, in urlopen
    chunked=chunked,
  File "f:\web scrapping\yelp\venv\lib\site-packages\urllib3\connectionpool.py", line 392, in _make_request
    conn.request(method, url, **httplib_request_kw)
  File "F:\programs\lib\http\client.py", line 1229, in request
    self._send_request(method, url, body, headers, encode_chunked)
  File "F:\programs\lib\http\client.py", line 1275, in _send_request
    self.endheaders(body, encode_chunked=encode_chunked)
  File "F:\programs\lib\http\client.py", line 1224, in endheaders
    self._send_output(message_body, encode_chunked=encode_chunked)
  File "F:\programs\lib\http\client.py", line 1016, in _send_output
    self.send(msg)
  File "F:\programs\lib\http\client.py", line 956, in send
    self.connect()
  File "f:\web scrapping\yelp\venv\lib\site-packages\urllib3\connection.py", line 187, in connect
    conn = self._new_conn()
  File "f:\web scrapping\yelp\venv\lib\site-packages\urllib3\connection.py", line 172, in _new_conn
    self, "Failed to establish a new connection: %s" % e
urllib3.exceptions.NewConnectionError: <urllib3.connection.HTTPConnection object at 0x0000012DC16B9248>: Failed to establish a new connection: [WinError 10061] No connection could be made because the target machine actively refused it

During handling of the above exception, another exception occurred:

Traceback (most recent call last):
  File "f:\web scrapping\yelp\venv\lib\site-packages\scrapy\utils\defer.py", line 117, in iter_errback
    yield next(it)
  File "f:\web scrapping\yelp\venv\lib\site-packages\scrapy\utils\python.py", line 345, in __next__
    return next(self.data)
  File "f:\web scrapping\yelp\venv\lib\site-packages\scrapy\utils\python.py", line 345, in __next__
    return next(self.data)
  File "f:\web scrapping\yelp\venv\lib\site-packages\scrapy\core\spidermw.py", line 64, in _evaluate_iterable
    for r in iterable:
  File "f:\web scrapping\yelp\venv\lib\site-packages\scrapy\spidermiddlewares\offsite.py", line 29, in process_spider_output
    for x in result:
  File "f:\web scrapping\yelp\venv\lib\site-packages\scrapy\core\spidermw.py", line 64, in _evaluate_iterable
    for r in iterable:
  File "f:\web scrapping\yelp\venv\lib\site-packages\scrapy\spidermiddlewares\referer.py", line 338, in <genexpr>
    return (_set_referer(r) for r in result or ())
  File "f:\web scrapping\yelp\venv\lib\site-packages\scrapy\core\spidermw.py", line 64, in _evaluate_iterable
    for r in iterable:
  File "f:\web scrapping\yelp\venv\lib\site-packages\scrapy\spidermiddlewares\urllength.py", line 37, in <genexpr>
    return (r for r in result or () if _filter(r))
  File "f:\web scrapping\yelp\venv\lib\site-packages\scrapy\core\spidermw.py", line 64, in _evaluate_iterable
    for r in iterable:
  File "f:\web scrapping\yelp\venv\lib\site-packages\scrapy\spidermiddlewares\depth.py", line 58, in <genexpr>
    return (r for r in result or () if _filter(r))
  File "f:\web scrapping\yelp\venv\lib\site-packages\scrapy\core\spidermw.py", line 64, in _evaluate_iterable
    for r in iterable:
  File "F:\web scrapping\yelpsecondinput\yelpdetails\yelpdetails\spiders\yelpspider.py", line 59, in parse
    print(driver.current_url)
  File "f:\web scrapping\yelp\venv\lib\site-packages\selenium\webdriver\remote\webdriver.py", line 669, in current_url
    return self.execute(Command.GET_CURRENT_URL)['value']
  File "f:\web scrapping\yelp\venv\lib\site-packages\selenium\webdriver\remote\webdriver.py", line 319, in execute
    response = self.command_executor.execute(driver_command, params)
  File "f:\web scrapping\yelp\venv\lib\site-packages\selenium\webdriver\remote\remote_connection.py", line 374, in execute
    return self._request(command_info[0], url, body=data)
  File "f:\web scrapping\yelp\venv\lib\site-packages\selenium\webdriver\remote\remote_connection.py", line 397, in _request
    resp = self._conn.request(method, url, body=body, headers=headers)
  File "f:\web scrapping\yelp\venv\lib\site-packages\urllib3\request.py", line 76, in request
    method, url, fields=fields, headers=headers, **urlopen_kw
  File "f:\web scrapping\yelp\venv\lib\site-packages\urllib3\request.py", line 97, in request_encode_url
    return self.urlopen(method, url, **extra_kw)
  File "f:\web scrapping\yelp\venv\lib\site-packages\urllib3\poolmanager.py", line 336, in urlopen
    response = conn.urlopen(method, u.request_uri, **kw)
  File "f:\web scrapping\yelp\venv\lib\site-packages\urllib3\connectionpool.py", line 765, in urlopen
    **response_kw
  File "f:\web scrapping\yelp\venv\lib\site-packages\urllib3\connectionpool.py", line 765, in urlopen
    **response_kw
  File "f:\web scrapping\yelp\venv\lib\site-packages\urllib3\connectionpool.py", line 765, in urlopen
    **response_kw
  File "f:\web scrapping\yelp\venv\lib\site-packages\urllib3\connectionpool.py", line 725, in urlopen
    method, url, error=e, _pool=self, _stacktrace=sys.exc_info()[2]
  File "f:\web scrapping\yelp\venv\lib\site-packages\urllib3\util\retry.py", line 439, in increment
    raise MaxRetryError(_pool, url, error or ResponseError(cause))
urllib3.exceptions.MaxRetryError: HTTPConnectionPool(host='127.0.0.1', port=63939): Max retries exceeded with url: /session/34fbd59411b86f639af2e0b16ea2b516/url (Caused by NewConnectionError('<urllib3.connection.HTTPConnection object at 0x0000012DC16B9248>: Failed to establish a new connection: [WinError 10061] No connection could be made because the target machine actively refused it'))
2020-06-02 21:42:12 [scrapy] INFO: Closing spider (finished)
